2020-08-13 14:56:12,800 - instabot version: 0.117.0 (bot) - INFO - Instabot version: 0.117.0 Started
2020-08-13 14:56:12,800 - instabot version: 0.117.0 (bot) - DEBUG - Bot imported from C:\Users\Gebruiker\Desktop\dev\channel_generator\venv\lib\site-packages\instabot\bot\bot.py
2020-08-13 15:09:03,552 - instabot version: 0.117.0 (api_login) - DEBUG - Loading cookies
2020-08-13 15:09:03,553 - instabot version: 0.117.0 (api_login) - DEBUG - Loading uuids
2020-08-13 15:09:03,553 - instabot version: 0.117.0 (api_login) - INFO - Recovery from C:\Users\Gebruiker\Desktop\dev\channel_generator\generator/config/puppies4nations_uuid_and_cookie.json: COOKIE True - UUIDs True - TIMING, DEVICE and ...
- user-agent=Instagram 117.0.0.28.123 Android (28/9.0; 420dpi; 1080x1920; OnePlus; ONEPLUS A3003; OnePlus3; qcom; en_US; 180322800)
- phone_id=e752e0e3-d108-407f-b5c2-f07f0000bed1
- uuid=9c721ac7-9e77-4bba-9152-ac7c7c0ecd03
- client_session_id=d9b8abc7-c734-41e8-a579-ce82e535e74b
- device_id=android-5ddf6083ddeebf63
2020-08-13 15:09:03,554 - instabot version: 0.117.0 (api_login) - INFO - LOGIN FLOW! Just logged-in: False
2020-08-13 15:09:14,959 - instabot version: 0.117.0 (api) - WARNING - HTTPSConnectionPool(host='i.instagram.com', port=443): Max retries exceeded with url: /api/v1/feed/timeline/ (Caused by NewConnectionError('<urllib3.connection.HTTPSConnection object at 0x0000020D6C910948>: Failed to establish a new connection: [Errno 11001] getaddrinfo failed'))
2020-08-13 15:09:26,671 - instabot version: 0.117.0 (api) - WARNING - HTTPSConnectionPool(host='i.instagram.com', port=443): Max retries exceeded with url: /api/v1/feed/reels_tray/ (Caused by NewConnectionError('<urllib3.connection.HTTPSConnection object at 0x0000020D6C689088>: Failed to establish a new connection: [Errno 11001] getaddrinfo failed'))
2020-08-13 15:09:26,683 - instabot version: 0.117.0 (api) - WARNING - HTTPSConnectionPool(host='i.instagram.com', port=443): Max retries exceeded with url: /api/v1/direct_v2/ranked_recipients/ (Caused by NewConnectionError('<urllib3.connection.HTTPSConnection object at 0x0000020D6C5E4F48>: Failed to establish a new connection: [Errno 11001] getaddrinfo failed'))
2020-08-13 15:09:26,693 - instabot version: 0.117.0 (api) - WARNING - HTTPSConnectionPool(host='i.instagram.com', port=443): Max retries exceeded with url: /api/v1/direct_v2/ranked_recipients/ (Caused by NewConnectionError('<urllib3.connection.HTTPSConnection object at 0x0000020D6C5E4F48>: Failed to establish a new connection: [Errno 11001] getaddrinfo failed'))
2020-08-13 15:09:26,705 - instabot version: 0.117.0 (api) - WARNING - HTTPSConnectionPool(host='i.instagram.com', port=443): Max retries exceeded with url: /api/v1/direct_v2/inbox/ (Caused by NewConnectionError('<urllib3.connection.HTTPSConnection object at 0x0000020D6C5F4448>: Failed to establish a new connection: [Errno 11001] getaddrinfo failed'))
2020-08-13 15:09:26,716 - instabot version: 0.117.0 (api) - WARNING - HTTPSConnectionPool(host='i.instagram.com', port=443): Max retries exceeded with url: /api/v1/direct_v2/get_presence/ (Caused by NewConnectionError('<urllib3.connection.HTTPSConnection object at 0x0000020D6C7AF088>: Failed to establish a new connection: [Errno 11001] getaddrinfo failed'))
2020-08-13 15:09:26,723 - instabot version: 0.117.0 (api) - WARNING - HTTPSConnectionPool(host='i.instagram.com', port=443): Max retries exceeded with url: /api/v1/news/inbox/?limited_activity=true&show_su=true (Caused by NewConnectionError('<urllib3.connection.HTTPSConnection object at 0x0000020D6C9108C8>: Failed to establish a new connection: [Errno 11001] getaddrinfo failed'))
2020-08-13 15:09:26,731 - instabot version: 0.117.0 (api) - WARNING - HTTPSConnectionPool(host='i.instagram.com', port=443): Max retries exceeded with url: /api/v1/users/profile_notice/ (Caused by NewConnectionError('<urllib3.connection.HTTPSConnection object at 0x0000020D6C9A3348>: Failed to establish a new connection: [Errno 11001] getaddrinfo failed'))
2020-08-13 15:09:26,743 - instabot version: 0.117.0 (api) - WARNING - HTTPSConnectionPool(host='i.instagram.com', port=443): Max retries exceeded with url: /api/v1/discover/explore/ (Caused by NewConnectionError('<urllib3.connection.HTTPSConnection object at 0x0000020D6C5E4488>: Failed to establish a new connection: [Errno 11001] getaddrinfo failed'))
2020-08-13 15:09:26,747 - instabot version: 0.117.0 (api) - INFO - Login flow failed, the cookie is broken. Relogin again.
2020-08-13 15:09:26,756 - instabot version: 0.117.0 (api_login) - DEBUG - Loading cookies
2020-08-13 15:09:26,756 - instabot version: 0.117.0 (api_login) - DEBUG - Loading uuids
2020-08-13 15:09:26,760 - instabot version: 0.117.0 (api_login) - INFO - Recovery from C:\Users\Gebruiker\Desktop\dev\channel_generator\generator/config/puppies4nations_uuid_and_cookie.json: COOKIE True - UUIDs True - TIMING, DEVICE and ...
- user-agent=Instagram 117.0.0.28.123 Android (28/9.0; 420dpi; 1080x1920; OnePlus; ONEPLUS A3003; OnePlus3; qcom; en_US; 180322800)
- phone_id=e752e0e3-d108-407f-b5c2-f07f0000bed1
- uuid=9c721ac7-9e77-4bba-9152-ac7c7c0ecd03
- client_session_id=84f543a9-7beb-4c4c-9c5e-7a90aba327ca
- device_id=android-5ddf6083ddeebf63
2020-08-13 15:09:26,760 - instabot version: 0.117.0 (api_login) - INFO - Not yet logged in starting: PRE-LOGIN FLOW!
2020-08-13 15:09:26,772 - instabot version: 0.117.0 (api) - WARNING - HTTPSConnectionPool(host='i.instagram.com', port=443): Max retries exceeded with url: /api/v1/accounts/get_prefill_candidates/ (Caused by NewConnectionError('<urllib3.connection.HTTPSConnection object at 0x0000020D6C8C05C8>: Failed to establish a new connection: [Errno 11001] getaddrinfo failed'))
2020-08-13 15:09:26,779 - instabot version: 0.117.0 (api) - WARNING - HTTPSConnectionPool(host='i.instagram.com', port=443): Max retries exceeded with url: /api/v1/qe/sync/ (Caused by NewConnectionError('<urllib3.connection.HTTPSConnection object at 0x0000020D6C910888>: Failed to establish a new connection: [Errno 11001] getaddrinfo failed'))
2020-08-13 15:09:26,787 - instabot version: 0.117.0 (api) - WARNING - HTTPSConnectionPool(host='i.instagram.com', port=443): Max retries exceeded with url: /api/v1/launcher/sync/ (Caused by NewConnectionError('<urllib3.connection.HTTPSConnection object at 0x0000020D6C9A3348>: Failed to establish a new connection: [Errno 11001] getaddrinfo failed'))
2020-08-13 15:09:26,799 - instabot version: 0.117.0 (api) - WARNING - HTTPSConnectionPool(host='i.instagram.com', port=443): Max retries exceeded with url: /api/v1/accounts/contact_point_prefill/ (Caused by NewConnectionError('<urllib3.connection.HTTPSConnection object at 0x0000020D6C92A208>: Failed to establish a new connection: [Errno 11001] getaddrinfo failed'))
2020-08-13 15:09:26,807 - instabot version: 0.117.0 (api) - WARNING - HTTPSConnectionPool(host='i.instagram.com', port=443): Max retries exceeded with url: /api/v1/accounts/login/ (Caused by NewConnectionError('<urllib3.connection.HTTPSConnection object at 0x0000020D6C5E3488>: Failed to establish a new connection: [Errno 11001] getaddrinfo failed'))
